[2023-06-17T03:10:42.463+0000] {taskinstance.py:1103} INFO - Dependencies all met for dep_context=non-requeueable deps ti=<TaskInstance: 7.3-filesensor.waiting_file scheduled__2023-06-16T00:00:00+00:00 [queued]>
[2023-06-17T03:10:42.472+0000] {taskinstance.py:1103} INFO - Dependencies all met for dep_context=requeueable deps ti=<TaskInstance: 7.3-filesensor.waiting_file scheduled__2023-06-16T00:00:00+00:00 [queued]>
[2023-06-17T03:10:42.473+0000] {taskinstance.py:1308} INFO - Starting attempt 1 of 1
[2023-06-17T03:10:42.482+0000] {taskinstance.py:1327} INFO - Executing <Task(FileSensor): waiting_file> on 2023-06-16 00:00:00+00:00
[2023-06-17T03:10:42.488+0000] {standard_task_runner.py:57} INFO - Started process 67903 to run task
[2023-06-17T03:10:42.492+0000] {standard_task_runner.py:84} INFO - Running: ['***', 'tasks', 'run', '7.3-filesensor', 'waiting_file', 'scheduled__2023-06-16T00:00:00+00:00', '--job-id', '157', '--raw', '--subdir', 'DAGS_FOLDER/7.3_file_sensor.py', '--cfg-path', '/tmp/tmpuzns32lm']
[2023-06-17T03:10:42.492+0000] {standard_task_runner.py:85} INFO - Job 157: Subtask waiting_file
[2023-06-17T03:10:42.538+0000] {task_command.py:410} INFO - Running <TaskInstance: 7.3-filesensor.waiting_file scheduled__2023-06-16T00:00:00+00:00 [running]> on host 5fef267ae46d
[2023-06-17T03:10:42.598+0000] {taskinstance.py:1547} INFO - Exporting env vars: AIRFLOW_CTX_DAG_OWNER='***' AIRFLOW_CTX_DAG_ID='7.3-filesensor' AIRFLOW_CTX_TASK_ID='waiting_file' AIRFLOW_CTX_EXECUTION_DATE='2023-06-16T00:00:00+00:00' AIRFLOW_CTX_TRY_NUMBER='1' AIRFLOW_CTX_DAG_RUN_ID='scheduled__2023-06-16T00:00:00+00:00'
[2023-06-17T03:10:42.617+0000] {taskinstance.py:1824} ERROR - Task failed with exception
Traceback (most recent call last):
  File "/home/airflow/.local/lib/python3.7/site-packages/airflow/sensors/base.py", line 225, in execute
    raise e
  File "/home/airflow/.local/lib/python3.7/site-packages/airflow/sensors/base.py", line 212, in execute
    poke_return = self.poke(context)
  File "/home/airflow/.local/lib/python3.7/site-packages/airflow/sensors/filesystem.py", line 61, in poke
    hook = FSHook(self.fs_conn_id)
  File "/home/airflow/.local/lib/python3.7/site-packages/airflow/hooks/filesystem.py", line 38, in __init__
    conn = self.get_connection(conn_id)
  File "/home/airflow/.local/lib/python3.7/site-packages/airflow/hooks/base.py", line 72, in get_connection
    conn = Connection.get_connection_from_secrets(conn_id)
  File "/home/airflow/.local/lib/python3.7/site-packages/airflow/models/connection.py", line 434, in get_connection_from_secrets
    raise AirflowNotFoundException(f"The conn_id `{conn_id}` isn't defined")
airflow.exceptions.AirflowNotFoundException: The conn_id `fs_default` isn't defined
[2023-06-17T03:10:42.629+0000] {taskinstance.py:1350} INFO - Marking task as FAILED. dag_id=7.3-filesensor, task_id=waiting_file, execution_date=20230616T000000, start_date=20230617T031042, end_date=20230617T031042
[2023-06-17T03:10:42.642+0000] {standard_task_runner.py:109} ERROR - Failed to execute job 157 for task waiting_file (The conn_id `fs_default` isn't defined; 67903)
[2023-06-17T03:10:42.664+0000] {local_task_job_runner.py:225} INFO - Task exited with return code 1
[2023-06-17T03:10:42.687+0000] {taskinstance.py:2651} INFO - 0 downstream tasks scheduled from follow-on schedule check
