[2023-06-11T00:13:00.761+0000] {taskinstance.py:1103} INFO - Dependencies all met for dep_context=non-requeueable deps ti=<TaskInstance: Monitero1.python-dummy scheduled__2023-06-10T00:00:00+00:00 [queued]>
[2023-06-11T00:13:00.796+0000] {taskinstance.py:1103} INFO - Dependencies all met for dep_context=requeueable deps ti=<TaskInstance: Monitero1.python-dummy scheduled__2023-06-10T00:00:00+00:00 [queued]>
[2023-06-11T00:13:00.797+0000] {taskinstance.py:1308} INFO - Starting attempt 1 of 1
[2023-06-11T00:13:00.813+0000] {taskinstance.py:1327} INFO - Executing <Task(PythonOperator): python-dummy> on 2023-06-10 00:00:00+00:00
[2023-06-11T00:13:00.821+0000] {standard_task_runner.py:57} INFO - Started process 17169 to run task
[2023-06-11T00:13:00.828+0000] {standard_task_runner.py:84} INFO - Running: ['***', 'tasks', 'run', 'Monitero1', 'python-dummy', 'scheduled__2023-06-10T00:00:00+00:00', '--job-id', '53', '--raw', '--subdir', 'DAGS_FOLDER/6.1_monitoreo.py', '--cfg-path', '/tmp/tmpvxr5_72g']
[2023-06-11T00:13:00.829+0000] {standard_task_runner.py:85} INFO - Job 53: Subtask python-dummy
[2023-06-11T00:13:00.896+0000] {task_command.py:410} INFO - Running <TaskInstance: Monitero1.python-dummy scheduled__2023-06-10T00:00:00+00:00 [running]> on host 5fef267ae46d
[2023-06-11T00:13:00.986+0000] {taskinstance.py:1547} INFO - Exporting env vars: AIRFLOW_CTX_DAG_OWNER='***' AIRFLOW_CTX_DAG_ID='Monitero1' AIRFLOW_CTX_TASK_ID='python-dummy' AIRFLOW_CTX_EXECUTION_DATE='2023-06-10T00:00:00+00:00' AIRFLOW_CTX_TRY_NUMBER='1' AIRFLOW_CTX_DAG_RUN_ID='scheduled__2023-06-10T00:00:00+00:00'
[2023-06-11T00:13:00.987+0000] {taskinstance.py:1824} ERROR - Task failed with exception
Traceback (most recent call last):
  File "/home/airflow/.local/lib/python3.7/site-packages/airflow/operators/python.py", line 181, in execute
    return_value = self.execute_callable()
  File "/home/airflow/.local/lib/python3.7/site-packages/airflow/operators/python.py", line 198, in execute_callable
    return self.python_callable(*self.op_args, **self.op_kwargs)
  File "/opt/airflow/dags/6.1_monitoreo.py", line 7, in myfunction
    raise Exception
Exception
[2023-06-11T00:13:00.999+0000] {taskinstance.py:1350} INFO - Marking task as FAILED. dag_id=Monitero1, task_id=python-dummy, execution_date=20230610T000000, start_date=20230611T001300, end_date=20230611T001300
[2023-06-11T00:13:01.007+0000] {standard_task_runner.py:109} ERROR - Failed to execute job 53 for task python-dummy (; 17169)
[2023-06-11T00:13:01.041+0000] {local_task_job_runner.py:225} INFO - Task exited with return code 1
[2023-06-11T00:13:01.058+0000] {taskinstance.py:2651} INFO - 0 downstream tasks scheduled from follow-on schedule check
