[2023-06-10T00:28:04.945+0000] {taskinstance.py:1103} INFO - Dependencies all met for dep_context=non-requeueable deps ti=<TaskInstance: Monitero1.tarea2 manual__2023-06-10T00:27:59.727096+00:00 [queued]>
[2023-06-10T00:28:04.954+0000] {taskinstance.py:1103} INFO - Dependencies all met for dep_context=requeueable deps ti=<TaskInstance: Monitero1.tarea2 manual__2023-06-10T00:27:59.727096+00:00 [queued]>
[2023-06-10T00:28:04.955+0000] {taskinstance.py:1308} INFO - Starting attempt 1 of 1
[2023-06-10T00:28:04.964+0000] {taskinstance.py:1327} INFO - Executing <Task(BashOperator): tarea2> on 2023-06-10 00:27:59.727096+00:00
[2023-06-10T00:28:04.972+0000] {standard_task_runner.py:57} INFO - Started process 13458 to run task
[2023-06-10T00:28:04.976+0000] {standard_task_runner.py:84} INFO - Running: ['***', 'tasks', 'run', 'Monitero1', 'tarea2', 'manual__2023-06-10T00:27:59.727096+00:00', '--job-id', '39', '--raw', '--subdir', 'DAGS_FOLDER/6.1_monitoreo.py', '--cfg-path', '/tmp/tmppq1o8u_9']
[2023-06-10T00:28:04.977+0000] {standard_task_runner.py:85} INFO - Job 39: Subtask tarea2
[2023-06-10T00:28:05.024+0000] {task_command.py:410} INFO - Running <TaskInstance: Monitero1.tarea2 manual__2023-06-10T00:27:59.727096+00:00 [running]> on host 5fef267ae46d
[2023-06-10T00:28:05.095+0000] {taskinstance.py:1547} INFO - Exporting env vars: AIRFLOW_CTX_DAG_OWNER='***' AIRFLOW_CTX_DAG_ID='Monitero1' AIRFLOW_CTX_TASK_ID='tarea2' AIRFLOW_CTX_EXECUTION_DATE='2023-06-10T00:27:59.727096+00:00' AIRFLOW_CTX_TRY_NUMBER='1' AIRFLOW_CTX_DAG_RUN_ID='manual__2023-06-10T00:27:59.727096+00:00'
[2023-06-10T00:28:05.097+0000] {subprocess.py:63} INFO - Tmp dir root location: 
 /tmp
[2023-06-10T00:28:05.098+0000] {subprocess.py:75} INFO - Running command: ['/bin/bash', '-c', "sleep 2 && echo 'Tarea 2"]
[2023-06-10T00:28:05.109+0000] {subprocess.py:86} INFO - Output:
[2023-06-10T00:28:05.114+0000] {subprocess.py:93} INFO - /bin/bash: -c: line 1: unexpected EOF while looking for matching `''
[2023-06-10T00:28:05.114+0000] {subprocess.py:93} INFO - /bin/bash: -c: line 2: syntax error: unexpected end of file
[2023-06-10T00:28:05.115+0000] {subprocess.py:97} INFO - Command exited with return code 2
[2023-06-10T00:28:05.127+0000] {taskinstance.py:1824} ERROR - Task failed with exception
Traceback (most recent call last):
  File "/home/airflow/.local/lib/python3.7/site-packages/airflow/operators/bash.py", line 211, in execute
    f"Bash command failed. The command returned a non-zero exit code {result.exit_code}."
airflow.exceptions.AirflowException: Bash command failed. The command returned a non-zero exit code 2.
[2023-06-10T00:28:05.132+0000] {taskinstance.py:1350} INFO - Marking task as FAILED. dag_id=Monitero1, task_id=tarea2, execution_date=20230610T002759, start_date=20230610T002804, end_date=20230610T002805
[2023-06-10T00:28:05.149+0000] {standard_task_runner.py:109} ERROR - Failed to execute job 39 for task tarea2 (Bash command failed. The command returned a non-zero exit code 2.; 13458)
[2023-06-10T00:28:05.194+0000] {local_task_job_runner.py:225} INFO - Task exited with return code 1
[2023-06-10T00:28:05.219+0000] {taskinstance.py:2651} INFO - 0 downstream tasks scheduled from follow-on schedule check
